Workbook

Sheet LEEME
B2: CRM COMERCIAL — KATANA + KIF
B3: Un solo archivo. Un solo pipeline. Se revisa cada lunes.
B6: CÓMO USARLO
B7: 1. LEADS | C7: Todo contacto vive aquí. Un renglón = una persona (no una empresa). Vacía primero tus bases existentes.
B8: 2. PIPELINE | C8: Solo deals con propuesta enviada o en negociación. Aquí se ve el dinero vs. la meta mensual.
B9: 3. TALENTOS | C9: Roster con verticales y estatus de media kit. Alimenta los dropdowns.
B10: 4. MARCAS TARGET | C10: El mapa de scouting por vertical (lo iremos llenando juntos, vertical por vertical).
B11: 5. AGENCIAS | C11: Agencias que manejan influencer marketing de las marcas target.
B12: 6. DASHBOARD | C12: Resumen automático: leads por estatus, dinero en pipeline vs. obligación mensual.
B13: 7. CATALOGOS | C13: Listas que alimentan los dropdowns. Si agregas un vertical o estatus nuevo, se agrega aquí.
B15: REGLAS DE ORO
B16: Regla 1 | C16: Ningún lead sin "Próximo paso" y fecha. Un lead sin próximo paso es un lead muerto.
B17: Regla 2 | C17: Tibio antes que frío: primero se trabaja la gente que ya te conoce.
B18: Regla 3 | C18: Meta viva: 8 propuestas activas en PIPELINE, siempre.
B19: Regla 4 | C19: Lunes = 20 min de revisión del DASHBOARD. Nada más.

Sheet HISTORIAL TALENTOS
A1: Fecha | B1: Talento | C1: Campo | D1: Valor anterior | E1: Valor nuevo | F1: Usuario | G1: Fuente | H1: Tipo de cambio | I1: Fila TALENTOS | J1: Request ID

Sheet PERFIL COMERCIAL — CAPTURA
A1: Llena SOLO las columnas D a H. El id, los nombres y el folder son técnicos: no los edites. Esta hoja NO captura estadísticas ni tarifas — esas viven en sus propias fuentes. NUNCA inventes logros, marcas ni cifras: si no lo puedes comprobar, déjalo vacío.
A2: talent_id | B2: canonical_name | C2: display_name | D2: Biografía breve | E2: Logros principales | F2: Colaboraciones y campañas | G2: Links de campañas exitosas | H2: Marcas relacionadas | I2: source_status | J2: library_folder_id | K2: Responsable | L2: Última actualización
A3: EJEMPLO | B3: — borrar esta fila — | C3: — borrar — | D3: [Qué hace, por qué importa, qué lo hace distinto. 40-60 palabras. Sin adjetivos vacíos.] | E3: [3 a 5 logros comprobables, separados por punto y coma. Con año cuando exista.] | F3: [Solo acuerdos REALES, separados por punto y coma. Una plática no es una colaboración.] | G3: [URLs publicadas, una por línea. Sin link, no va la campaña.] | H3: [Marcas afines a las que le pega, aunque no haya trabajado con ellas. Esta sí es aspiracional.] | I3: PENDIENTE
A4: KT-001 | B4: Divino Espinoza | C4: Divino Espinoza | I4: PENDIENTE | J4: 1LJV7J41pYCuLaLkPNYVRdIrqWKMBjRgm | K4: Jesús
A5: KT-002 | B5: Lazy Boy | C5: Lazy Boy | I5: PENDIENTE | J5: 1FJuLZ5coA36tdK4eDM8uTqnwMNm872hm | K5: Jesús
A6: KT-003 | B6: Luis Pride | C6: Luis Pride | I6: PENDIENTE | J6: 1UjZkcQ_T4pLVxujZhh4ME1fP87N-4gby | K6: Jesús
A7: KT-004 | B7: Ronaldo BXM | C7: Ronaldo BXM | I7: PENDIENTE | J7: 1aA5WfpiPjF3tAhzTxXIQmu7MuryCVeuo | K7: Jesús
A8: KT-005 | B8: Tejon de la Miel | C8: Tejón de la Miel | I8: PENDIENTE | J8: 1la5czIUdiZO1ilJxnaMHSNObFjeE0jhC | K8: Jesús
A9: KT-006 | B9: Mama Tejona | C9: Mamá Tejona | I9: PENDIENTE | J9: 10wR2gldOS8ouOiHJwtIS4fr1hES1mRuc | K9: Jesús
A10: KT-007 | B10: Cesar de la Parra | C10: César de la Parra | I10: PENDIENTE | J10: 1Nzq8tDH1gPeE5uOgpOaD0SELM6PaAsTp | K10: Jesús
A11: KT-008 | B11: Mar Coronel | C11: Mar Coronel | I11: PENDIENTE | J11: 1saKx4zCLWHkzv8t_U7UYfY684cXkcjpA | K11: Jesús
A12: KT-009 | B12: Nene Creative | C12: Nene Creative | I12: PENDIENTE | J12: 1SqyS83UWl7ZDs_YZSaEIFw8seoO7gcp7 | K12: Jesús
A13: KT-010 | B13: Julio Orozco | C13: Julio Orozco | I13: PENDIENTE | J13: 1MAsj4wz6UrtFjt_fvL8EIq4rPA57mWMx | K13: Jesús
A14: KT-011 | B14: Mariel Estrella | C14: Mariel Estrella | I14: PENDIENTE | J14: 1ckIvy8oUklftpUARy2DuyYQowggb-MaP | K14: Jesús
A15: KT-012 | B15: Tony Gastelum | C15: Tony Gastélum | I15: PENDIENTE | J15: 1hXOEB4LV3icf6uO-otLv1m_DYXXHRCf0 | K15: Jesús
... A24: KT-028 | B24: Padigol | C24: Padigol | I24: PENDIENTE | J24: 1DZO6m1Om0i5NIYPDgLYkTZeT5B4YkbM9 | K24: Jesús

Sheet DASHBOARD
B2: DASHBOARD COMERCIAL
B3: Se actualiza solo. Revisar cada lunes, 20 minutos.
B5: OBLIGACIÓN MENSUAL (MXN) | C5: 140000 | D5: ← Editable (Rivaldo). Si se renegocia, cámbialo aquí. | F5: LEADS ACTIVOS SIN PRÓXIMO PASO | G5: =COUNTIFS(LEADS!B:B,"<>",LEADS!R:R,"",LEADS!P:P,"<>Cerrado GANADO",LEADS!P:P,"<>Cerrado PERDIDO",LEADS!P:P,"<>Dormido") -> 1
F6: Meta: 0. Un lead sin próximo paso es un lead muerto.
B7: PROPUESTAS ACTIVAS (meta: 8) | C7: =COUNTIF(PIPELINE!F:F,"Propuesta enviada")+COUNTIF(PIPELINE!F:F,"Negociación")+COUNTIF(PIPELINE!F:F,"Contrato") -> 2
B8: FEE EN PIPELINE (total, MXN) | C8: =SUMIFS(PIPELINE!I:I,PIPELINE!F:F,"<>Cerrado PERDIDO",PIPELINE!F:F,"<>Cerrado GANADO",PIPELINE!F:F,"<>") -> 230000
B9: FEE PONDERADO (realista, MXN) | C9: =SUMIFS(PIPELINE!J:J,PIPELINE!F:F,"<>Cerrado PERDIDO",PIPELINE!F:F,"<>Cerrado GANADO",PIPELINE!F:F,"<>") -> 137500
B10: GANADO (fee cerrado, MXN) | C10: =SUMIFS(PIPELINE!I:I,PIPELINE!F:F,"Cerrado GANADO") -> 120000
B12: FEE PONDERADO POR MES DE COBRO | F12: LEADS POR ESTATUS
B13: Mes | C13: Fee ponderado | D13: vs. obligación | F13: Estatus | G13: Cuenta
B14: Jul 2026 | C14: =SUMIFS(PIPELINE!J:J,PIPELINE!L:L,B14,PIPELINE!F:F,"<>Cerrado PERDIDO") -> 0 | D14: =IF(C14="","",C14-$C$5) -> -140000 | F14: Por contactar | G14: =COUNTIF(LEADS!P:P,F14) -> 1
B15: Ago 2026 | C15: =SUMIFS(PIPELINE!J:J,PIPELINE!L:L,B15,PIPELINE!F:F,"<>Cerrado PERDIDO") -> 0 | D15: =IF(C15="","",C15-$C$5) -> -140000 | F15: Contactado | G15: =COUNTIF(LEADS!P:P,F15) -> 0
B16: Sep 2026 | C16: =SUMIFS(PIPELINE!J:J,PIPELINE!L:L,B16,PIPELINE!F:F,"<>Cerrado PERDIDO") -> 0 | D16: =IF(C16="","",C16-$C$5) -> -140000 | F16: En conversación | G16: =COUNTIF(LEADS!P:P,F16) -> 1
B17: Oct 2026 | C17: =SUMIFS(PIPELINE!J:J,PIPELINE!L:L,B17,PIPELINE!F:F,"<>Cerrado PERDIDO") -> 0 | D17: =IF(C17="","",C17-$C$5) -> -140000 | F17: Reunión agendada | G17: =COUNTIF(LEADS!P:P,F17) -> 0
B18: Nov 2026 | C18: =SUMIFS(PIPELINE!J:J,PIPELINE!L:L,B18,PIPELINE!F:F,"<>Cerrado PERDIDO") -> 0 | D18: =IF(C18="","",C18-$C$5) -> -140000 | F18: Propuesta enviada | G18: =COUNTIF(LEADS!P:P,F18) -> 0
B19: Dic 2026 | C19: =SUMIFS(PIPELINE!J:J,PIPELINE!L:L,B19,PIPELINE!F:F,"<>Cerrado PERDIDO") -> 0 | D19: =IF(C19="","",C19-$C$5) -> -140000 | F19: Negociación | G19: =COUNTIF(LEADS!P:P,F19) -> 0
B20: Ene 2027 | C20: =SUMIFS(PIPELINE!J:J,PIPELINE!L:L,B20,PIPELINE!F:F,"<>Cerrado PERDIDO") -> 0 | D20: =IF(C20="","",C20-$C$5) -> -140000 | F20: Cerrado GANADO | G20: =COUNTIF(LEADS!P:P,F20) -> 0
F21: Cerrado PERDIDO | G21: =COUNTIF(LEADS!P:P,F21) -> 0
F22: Dormido | G22: =COUNTIF(LEADS!P:P,F22) -> 0

Sheet CATALOGOS
A1: VERTICALES | B1: TIPO DE LEAD | C1: ESTATUS LEAD | D1: TEMPERATURA | E1: PRIORIDAD | F1: UNIDAD DE NEGOCIO | G1: TALENTOS | H1: RESPONSABLE | I1: ETAPA DEAL | J1: PROBABILIDAD
A2: Bebidas | B2: Marca directa | C2: Por contactar | D2: Caliente (ya trabajamos) | E2: P1 - Esta semana | F2: KIF (campañas) | G2: Pool Combate (paquete) | H2: Chuy | I2: Propuesta enviada | J2: 25%
A3: Alimentos & Gastro | B3: Agencia creativa | C3: Contactado | D3: Tibio (nos conoce) | E3: P2 - Este mes | F3: Katana (talento casa) | G3: Divino Espinoza | H3: Ramiro | I3: Negociación | J3: 50%
A4: Apuestas & Fantasy | B4: Agencia de medios | C4: En conversación | D4: Frío (scouting) | E4: P3 - Después | F4: FIERA | G4: Lacy Way | H4: Paty | I4: Contrato | J4: 75%
A5: Tech & Telecom | B5: Agencia influencer mkt | C5: Reunión agendada | F5: Fórmula S | G5: Luis Pride | H5: Otro | I5: Cerrado GANADO | J5: 90%
A6: Gaming & Esports | B6: Agencia PR | C6: Propuesta enviada | F6: DOPA/Park8 | G6: Ronny | I6: Cerrado PERDIDO
A7: Sportswear & Nutrición | B7: BTL / Experiential | C7: Negociación | G7: Tejón de la Miel
A8: Belleza & Wellness | B8: Productora | C8: Cerrado GANADO | G8: Tejón + Mamá (dupla familiar)
A9: Streaming & Entretenimiento | B9: Plataforma | C9: Cerrado PERDIDO | G9: César de la Parra
A10: Familia & Kids | B10: Sponsor | C10: Dormido | G10: Mar Coronel
A11: Financiero & Fintech | B11: Aliado comercial | G11: Nene Creative
A12: Otro | G12: Julio Orozco
G13: Mariel Estrella
G14: Mariely
G15: Talento aliado (externo)
G16: Varios / Pool mixto

Sheet LEADS
A1: SEÑALÉTICA: | B1: ACTIVO — ya hay contacto real / cerrado | C1: A UN PASO — contrato / por firmar | D1: EN PROCESO — negociación / propuesta / tibio | E1: FRÍO — target, aún sin contactar | F1: PERDIDO / DORMIDO — reactivar o descartar
A2: ID | B2: Empresa | C2: Tipo | D2: Vertical | E2: Contacto (nombre) | F2: Cargo | G2: Email | H2: Teléfono / WhatsApp | I2: LinkedIn | J2: Ciudad | K2: Temperatura | L2: Prioridad | M2: Unidad de negocio | N2: Talento recomendado | O2: Idea de campaña / ángulo | P2: Estatus | Q2: Último contacto | R2: Próximo paso | S2: Fecha próximo paso | T2: Responsable | U2: Fuente | V2: Notas
A3: =IF(B2="","","L"&TEXT(ROW()-1,"000")) -> L002 | B3: Cerveza Victoria | C3: Marca directa | D3: Bebidas | E3: (nombre del contacto) | F3: Brand Manager | J3: CDMX | K3: Tibio (nos conoce) | L3: P1 - Esta semana | M3: KIF (campañas) | N3: Pool Combate (paquete) | O3: Pool combate + activación en función | P3: Por contactar | R3: Mandar media kit y pedir llamada | T3: Chuy | U3: Relación previa | V3: EJEMPLO — borra este renglón
A4: L003 | B4: Paramount Pictures | C4: Plataforma | D4: Streaming & Entretenimiento | E4: Aureliano “Aure” Domínguez / María Constela Olivares | F4: PR / Películas (cargo exacto pendiente) | G4: Aureliano_Dominguez@paramount.com / Maria.ConstelaOlivares@paramount.com | J4: CDMX | K4: Tibio (nos conoce) | L4: P2 - Este mes | M4: Katana (talento casa) | N4: Varios / Pool mixto | O4: PR por estreno: premieres, junkets, experiencias y contenido con talento según cada película. Street Fighter en seguimiento. | P4: En conversación | Q4: 2026-08-03 | R4: Esperar respuesta de Aure sobre Street Fighter y pedir próximos títulos/oportunidades de PR. Solicitar de nuevo enlace con Félix por separado. | T4: Chuy | U4: Relación directa / junta Paramount 2026-06-03 | V4: Relación principalmente de PR y normalmente sin paga; ocasionalmente puede haber presupuesto. No existe calendario de estrenos ni fechas confirmadas en las fuentes. Mantener Paramount Películas separado de Paramount Social/UFC.
A5: =IF(B4="","","L"&TEXT(ROW()-1,"000")) -> L004
A6: =IF(B5="","","L"&TEXT(ROW()-1,"000"))
A7: =IF(B6="","","L"&TEXT(ROW()-1,"000"))
A8: =IF(B7="","","L"&TEXT(ROW()-1,"000"))
A9: =IF(B8="","","L"&TEXT(ROW()-1,"000"))
A10: =IF(B9="","","L"&TEXT(ROW()-1,"000"))
A11: =IF(B10="","","L"&TEXT(ROW()-1,"000"))
A12: =IF(B11="","","L"&TEXT(ROW()-1,"000"))
A13: =IF(B12="","","L"&TEXT(ROW()-1,"000"))
A14: =IF(B13="","","L"&TEXT(ROW()-1,"000"))
A15: =IF(B14="","","L"&TEXT(ROW()-1,"000"))
A16: =IF(B15="","","L"&TEXT(ROW()-1,"000"))
... A501: =IF(B500="","","L"&TEXT(ROW()-1,"000"))

Sheet PIPELINE
A1: SEÑALÉTICA: | B1: ACTIVO — ya hay contacto real / cerrado | C1: A UN PASO — contrato / por firmar | D1: EN PROCESO — negociación / propuesta / tibio | E1: FRÍO — target, aún sin contactar | F1: PERDIDO / DORMIDO — reactivar o descartar
A2: ID Deal | B2: Empresa | C2: Unidad de negocio | D2: Talento | E2: Descripción del deal | F2: Etapa | G2: Probabilidad | H2: Monto total (MXN) | I2: Fee neto Katana/KIF (MXN) | J2: Fee ponderado (MXN) | K2: Mes de cierre esperado | L2: Mes de cobro esperado | M2: Responsable | N2: Próximo paso | O2: Fecha próximo paso | P2: Notas
A3: =IF(B3="","","D"&TEXT(ROW()-2,"000")) -> D001 | B3: Gatorade (vía Affluency / FCO Group) | C3: KIF (campañas) | D3: Mariel Estrella | E3: Propuesta preliminar para Gatorade dirigida a Gen Z y Millennials. Scope solicitado: 1 Reel + 1 TikTok + 1 mes de pauta + 1 mes de exclusividad. Afluency preguntó si podía cerrarse en $120,000 MXN; Chuy indicó que $140,000 MXN sería el mínimo viable y aclaró que la propuesta previa no incluía pauta ni exclusividad. | F3: Negociación preliminar / sin brief final | G3: 50% | H3: 140000 | I3: 140000 | J3: 70000 | K3: Ago 2026 | M3: Chuy | N3: Esperar brief formal y respuesta de Gatorade/Affluency. No aprobar $120,000 MXN sin revisar exactamente si Reel y TikTok son piezas distintas o espejo, así como términos de pauta y exclusividad. | O3: 2026-08-04 | P3: Evidencia por WhatsApp: objetivo de awareness para Gen Z y Millennials; scope preliminar de 1 Reel, 1 TikTok, 1 mes de pauta y 1 mes de exclusividad. Afluency propuso $120,000 MXN o dos Reels; Chuy señaló $140,000 MXN como máximo ajuste posible dentro de precio paquete. Brief aún no disponible. No marcar como aprobado, cerrado ni tarifa final autorizada hasta recibir brief y confirmar derechos.
A4: =IF(B4="","","D"&TEXT(ROW()-2,"000")) -> D002 | B4: Canal MX (vía agencia Padrinito) | C4: KIF (campañas) | D4: Wereverwero | E4: Audio — campaña Canal MX | F4: Cerrado GANADO | G4: 100% | H4: 90000 | I4: 90000 | J4: =IF(OR(I4="",G4=""),"",I4*VALUE(SUBSTITUTE(G4,"%",""))/100) -> 90000 | K4: Jul 2026 | L4: Ramiro | M4: Dar seguimiento a entrega (Wereverwero "no tarda") | N4: Cerrado por Ramiro
A5: =IF(B5="","","D"&TEXT(ROW()-2,"000")) -> D003 | B5: Canal MX (vía agencia Padrinito) | C5: KIF (campañas) | D5: Mike Máquina del Mal | E5: Audio — campaña Canal MX | F5: Cerrado GANADO | G5: 100% | H5: 30000 | I5: 30000 | J5: =IF(OR(I5="",G5=""),"",I5*VALUE(SUBSTITUTE(G5,"%",""))/100) -> 30000 | K5: Jul 2026 | L5: Ramiro | M5: Confirmar entrega recibida y facturar | N5: Cerrado por Ramiro. Monto aprox. ("creo 30 mil") — confirmar exacto
A6: =IF(B6="","","D"&TEXT(ROW()-2,"000")) -> D004 | B6: Canal MX (vía agencia Padrinito) | C6: KIF (campañas) | D6: Mercedes Roa | E6: Audio — campaña Canal MX | F6: Negociación | G6: 75% | H6: 90000 | I6: 90000 | J6: =IF(OR(I6="",G6=""),"",I6*VALUE(SUBSTITUTE(G6,"%",""))/100) -> 67500 | K6: Ago 2026 | L6: Ramiro | M6: Cerrar monto y firmar
A7: D006 | B7: VERSUS BET (vía VKNG Group) | C7: Katana (talento casa) | D7: Tony Gastélum | E7: 1 TikTok + espejo en Instagram Reels + derechos de pauta en TikTok por 30 días | F7: Negociación | G7: 0.75 | H7: 35000 | K7: Ago 2026 | M7: Ramiro | N7: Negociar el cierre en $45,000 MXN y confirmar condiciones finales con VKNG Group / VERSUS BET | O7: 2026-08-04 | P7: Condición corregida: pago a 90 días hábiles. Tony ya aceptó $35,000 MXN como punto de partida. Ramiro busca subir el deal a $45,000 MXN. Responsable comercial: Ramiro. Mantener como negociación hasta confirmación final del cliente.
A8: D007 | B8: Gamergy | C8: Katana (talento casa / IP) | D8: Nene Creative | E8: Propuesta de seguimiento para llegar con concepto de torneo de FC Mobile + participación de Nene Creative. | F8: En proceso — seguimiento / propuesta por desarrollar | G8: 35% | K8: Ago 2026 | M8: Chuy | N8: Dar seguimiento a Gamergy y preparar propuesta concreta de torneo FC Mobile con Nene Creative. | P8: No inventar presupuesto, alcance ni derechos. Definir formato del torneo, rol de Nene, fechas, sede/plataforma, producción y patrocinadores antes de cotizar.
A9: D008 | B9: Goodyear | C9: KIF (campañas) | D9: Por definir | E9: Campaña con presupuesto total de $120,000 MXN. Se evalúan uno o varios talentos para cubrir el alcance dentro del presupuesto. | F9: En proceso — armado de opciones | G9: 35% | H9: 120000 | K9: Ago 2026 | M9: Ramiro | N9: Definir qué talento puede cubrir todo el alcance por $120,000 MXN y armar una o varias opciones para presentar. | P9: Perfiles revisados: Chuy Almada, Ronny BXM, Luis Pride, Juan de Dios García y Yozz. No hay talento seleccionado ni propuesta aprobada. Ramiro acomodará entregables y propondrá la mejor opción dentro del presupuesto. Confirmar si el monto incluye IVA, pauta y derechos.
A10: D009 | B10: Banx / Banxs (Gera) | C10: Katana — PR, lanzamiento e influencers | D10: Por definir | E10: Nuevo banco o neobanco próximo a lanzarse al mercado. Posible iguala para dar a conocer el producto, generar conversiones y aperturas de cuenta mediante PR, líderes de opinión e influencers. | F10: Descubrimiento — reunión inicial | K10: Ago 2026 | M10: Chuy | N10: Escuchar objetivos, producto, audiencia, fecha de lanzamiento, alcance esperado, KPIs, presupuesto y duración de la posible iguala. Definir siguiente paso para propuesta. | O10: 2026-08-04 | P10: No asumir todavía que el alcance está cerrado. Confirmar nombre comercial, estatus regulatorio, funcionalidades disponibles, mensajes permitidos, responsables internos y si buscan campaña puntual o iguala mensual. No prometer talentos, métricas ni resultados antes del brief.
A11: D010 | B11: Supernova — Luis Pride | C11: Katana — talento / negociación | D11: Luis Pride | E11: Negociación para participación de Luis Pride en Supernova. Alan Tamayo ofreció $500,000 MXN; Chuy abrió en $550,000 MXN y buscará mejorar la oferta antes de cerrar. | F11: Negociación activa | G11: 0.75 | H11: 500000 | K11: Ago 2026 | M11: Chuy | N11: Esperar respuesta de Alan Tamayo, empujar la cifra por arriba de $500,000 MXN y cerrar condiciones finales con Luis Pride. | O11: 2026-08-04 | P11: Oferta actual confirmada: $500,000 MXN. Ancla inicial de Chuy: $550,000 MXN. Antes de cerrar, confirmar IVA, viáticos, hospedaje, exclusividad, derechos de imagen, publicaciones, apariciones previas, forma de pago, cancelación y penalizaciones. No marcar como cerrado hasta tener aceptación y condiciones completas.
A12: D011 | B12: Supernova — Gera MX vs Lit Killah | C12: Katana — talento / negociación | D12: Gera MX | E12: Oportunidad para cerrar a Gera MX como rival de Lit Killah en Supernova. Lit Killah ya está puesto. Chuy llevará directamente el cierre y la negociación de Gera MX. | F12: Contacto iniciado / negociación por abrir | G12: 0.35 | K12: Ago 2026 | M12: Chuy | N12: Dar seguimiento a Durán, personal manager de Gera MX, para confirmar interés formal, disponibilidad y expectativa económica; después abrir negociación y cerrar a Gera. | O12: 2026-08-05 | P12: Lit Killah está confirmado y dispuesto. Mensaje ya enviado a Durán. No registrar la pelea como cerrada hasta tener aceptación formal de Gera MX y acuerdo económico y contractual.
A13: =IF(B13="","","D"&TEXT(ROW()-2,"000")) | J13: =IF(OR(I13="",G13=""),"",I13*VALUE(SUBSTITUTE(G13,"%",""))/100)
A14: =IF(B14="","","D"&TEXT(ROW()-2,"000")) | J14: =IF(OR(I14="",G14=""),"",I14*VALUE(SUBSTITUTE(G14,"%",""))/100)
A15: =IF(B15="","","D"&TEXT(ROW()-2,"000")) | J15: =IF(OR(I15="",G15=""),"",I15*VALUE(SUBSTITUTE(G15,"%",""))/100)
A16: =IF(B16="","","D"&TEXT(ROW()-2,"000")) | J16: =IF(OR(I16="",G16=""),"",I16*VALUE(SUBSTITUTE(G16,"%",""))/100)
A17: =IF(B17="","","D"&TEXT(ROW()-2,"000")) | J17: =IF(OR(I17="",G17=""),"",I17*VALUE(SUBSTITUTE(G17,"%",""))/100)
A18: =IF(B18="","","D"&TEXT(ROW()-2,"000")) | J18: =IF(OR(I18="",G18=""),"",I18*VALUE(SUBSTITUTE(G18,"%",""))/100)
A19: =IF(B19="","","D"&TEXT(ROW()-2,"000")) | J19: =IF(OR(I19="",G19=""),"",I19*VALUE(SUBSTITUTE(G19,"%",""))/100)
A20: =IF(B20="","","D"&TEXT(ROW()-2,"000")) | J20: =IF(OR(I20="",G20=""),"",I20*VALUE(SUBSTITUTE(G20,"%",""))/100)
A21: =IF(B21="","","D"&TEXT(ROW()-2,"000")) | J21: =IF(OR(I21="",G21=""),"",I21*VALUE(SUBSTITUTE(G21,"%",""))/100)
A22: =IF(B22="","","D"&TEXT(ROW()-2,"000")) | J22: =IF(OR(I22="",G22=""),"",I22*VALUE(SUBSTITUTE(G22,"%",""))/100)
A23: =IF(B23="","","D"&TEXT(ROW()-2,"000")) | J23: =IF(OR(I23="",G23=""),"",I23*VALUE(SUBSTITUTE(G23,"%",""))/100)
A24: =IF(B24="","","D"&TEXT(ROW()-2,"000")) | J24: =IF(OR(I24="",G24=""),"",I24*VALUE(SUBSTITUTE(G24,"%",""))/100)
... A251: =IF(B251="","","D"&TEXT(ROW()-2,"000")) | J251: =IF(OR(I251="",G251=""),"",I251*VALUE(SUBSTITUTE(G251,"%",""))/100)

Sheet TALENTOS
A1: Talento | B1: Categoría | C1: Verticales que abre | D1: Tipo (casa / aliado) | E1: IG seguidores | F1: TikTok seguidores | G1: YouTube subs | H1: Otras plataformas | I1: Media kit HTML | J1: Tarifa base referencia (MXN) | K1: Notas / ángulo comercial | V1: País / mercado | W1: Estatus network | X1: Prioridad comercial | Y1: Disponibilidad | Z1: Foto principal | AA1: Bio corta | AB1: Campañas / casos | AC1: Logros | AD1: Videos | AE1: Fecha de corte métricas | AF1: Fuente métricas | AG1: Notas operativas | AH1: Última actualización | AI1: Actualizado por
A2: Luis Pride | B2: MMA | C2: Bebidas, Apuestas, Sportswear, Nutrición | D2: KATANA — Casa | I2: Pendiente | J2: Ver Tarifario Maestro 2026 | K2: Activo premium de box. La cifra de $750,000 MXN aplica como referencia para presencia de marca en el short durante el combate. Puede ampliarse a ropa de entrenamiento, llegada, pesaje, conferencia o contenido asociado según el paquete. Sujeto a evento, rival, transmisión, ubicación del logo, derechos, exclusividad y aprobación final. Fuente: definición interna Chuy, 31-jul-2026. Pendiente aprobación de Ramiro.
A3: Ronny | B3: Box / Creator / Coach | C3: Box, Combate, Sportswear, Nutrición, Apuestas, Bebidas, Fitness | D3: KATANA — Casa | E3: 958000 | F3: 1100000 | G3: 23300 | H3: Twitch principal | Kick disponible | I3: https://drive.google.com/file/d/1TWMAP6Ak43b1IMU3mSScKstMW9jvHAjA/view | J3: Ver Tarifario Maestro 2026 | K3: PILOTO — FASE 1. Métricas capturadas del roster operativo: Instagram 958K, TikTok 1.1M y YouTube 23.3K; requieren validación de fecha de corte antes de usarse con cliente. Media kit V1 localizado en Drive. Existen al menos tres copias del mismo HTML; pendiente declarar una sola versión maestra y archivar duplicados. Tarifario en revisión de Ramiro. | X3: PILOTO — FASE 1
A4: Tejón de la Miel | B4: Box — Promesa | C4: Familia & Kids, Sportswear, Alimentos | D4: KATANA — Casa | I4: Pendiente | J4: Ver Tarifario Maestro 2026 | K4: Regla de espejo aplicada: 1.5x el precio más alto entre TikTok y Reel IG. Fee base por pelear: $450,000 MXN. Fuente: definición interna Chuy, 31-jul-2026.
A5: Divino Espinoza | B5: Box — Campeón del mundo | C5: Bebidas, Apuestas, Sportswear, Streaming | D5: KATANA — Casa | I5: Pendiente | J5: Caso por caso | K5: Streamer también activo en Twitch. La tarifa de stream registrada corresponde a Twitch. Fee base por pelear: $250,000 MXN. Fuente: Tabulador HONOR + ajustes internos de Chuy, 31-jul-2026. Propuesta interna pendiente de aprobación de Ramiro.
A6: Lazy Boy | B6: MMA / UFC | C6: Bebidas, Apuestas, Sportswear, Grooming | D6: KATANA — Aliado (definir) | I6: Pendiente | J6: Caso por caso | K6: TikTok igual a Mariel Estrella. Reel IG corregido a $150,000 y Reel Collab a $180,000. Peleas desde $50,000 MXN, sujeto a rival, evento, transmisión, ciudad, viáticos, exposición de marca y condiciones deportivas. Menor de edad: requiere autorización de tutor, revisión legal y aprobación interna. Fuente: definición interna Chuy, 31-jul-2026. Pendiente aprobación de Ramiro.
A7: César de la Parra | B7: Chef — Alto perfil | C7: Alimentos & Gastro, Bebidas, Electrodomésticos, Delivery, Turismo | D7: KATANA — Acceso exclusivo | I7: Pendiente | J7: Caso por caso | K7: Perfil altamente selectivo. Solo considerar marcas con afinidad real y aprobación expresa del talento. Priorizar acuerdos anuales, embajadurías de largo plazo o proyectos extraordinarios con alto valor creativo, gastronómico o reputacional. No manejar tarifario estándar ni cotizar por pieza aislada salvo excepción estratégica. Fuente: definición interna Chuy, 31-jul-2026. Requiere revisión de Jesús y Ramiro antes de presentar.
A8: Mariel Estrella | B8: Fitness / Lifestyle / Wellness | C8: Fitness, Wellness, Sportswear, Belleza, Healthy food | D8: KATANA — Casa | I8: Pendiente | J8: Ver Tarifario Maestro 2026 | K8: PENDIENTE: completar bio, propuesta de valor, plataformas, métricas, assets, casos y restricciones. La nota anterior de pronósticos/apuestas no correspondía a este perfil. | X8: PILOTO — FASE 1
A9: Mariely Coronel | B9: Fútbol | C9: Apuestas, Bebidas, Snacks, Telcos | D9: KATANA — Casa | I9: Pendiente | J9: Ver Tarifario Maestro 2026 | K9: Twitch es su plataforma principal de streaming. Stream dedicado para marca: $120,000 MXN por hora. Integraciones dentro de streams existentes se cotizan caso por caso. YouTube disponible: video dedicado, integración y Short; tarifas pendientes. Fuente: definición interna Chuy, 31-jul-2026. Pendiente aprobación de Ramiro.
A10: Nene Creative | B10: Gaming / Esports / Streaming | C10: Gaming, Esports, Tech, Telecom, Automotriz, Energy | D10: KATANA — Casa | H10: Kick | Twitch | YouTube | I10: Pendiente | J10: Ver Tarifario Maestro 2026 | K10: Kick es su plataforma principal de streaming. YouTube disponible: video dedicado, integración dentro de video y Short; tarifas pendientes. Fuente: definición interna Chuy, 31-jul-2026. Propuesta interna pendiente de aprobación de Ramiro. | X10: PILOTO — FASE 1
A11: Julio Orozco | B11: Música / Podcast / IRL | C11: Bebidas, Festivales, Ticketing, Moda, Nightlife | D11: KATANA — Casa | H11: Kick | YouTube | I11: Pendiente | J11: Ver Tarifario Maestro 2026 | K11: Cierres en curso — empujar.
A12: Juan de Dios García | B12: Storytime / Vlogging | C12: Entretenimiento, Bebidas, Apps | D12: KATANA — Operable | H12: @juanddiosg | I12: Pendiente | J12: Ver Tarifario Maestro 2026 | K12: POSIBLE DUPLICADO: ¿Mariely = Mar Coronel (Marieli Coronel)? Confirmar y consolidar.
A13: Mamá Tejona | B13: Familia / Lifestyle / Box | C13: Familia & Kids, Sportswear, Alimentos, Wellness | D13: KATANA — Ecosistema Tejón | E13: 350000 | I13: Pendiente | J13: Ver Tarifario Maestro 2026 | K13: Tarifario construido con definición directa de Chuy. TikTok + réplica espejo en Reel se mantiene por encima del TikTok individual. Publicación fijada durante 7 días y exclusividad mensual se cotizan por separado. TikTok audio musical: pendiente de definir. Fuente: definición interna Chuy, 31-jul-2026. No incluye IVA, producción, viáticos, pauta ni derechos de uso adicionales.
A14: Tony Gastélum | B14: Calistenia / Fitness | C14: Sportswear, Fitness, Nutrición, Wellness, Tech deportiva | D14: KATANA — Casa | I14: Pendiente | J14: Ver Tarifario Maestro 2026 | K14: Rates altos; propuesto Viuda de Romero $4M | X14: PILOTO — FASE 1
A15: Mike Máquina del Mal | B15: Streamer / Fútbol | C15: Fútbol, Apuestas, Gaming, Streaming | D15: KATANA — Operable | H15: YouTube Live | Twitch | Kick | I15: Pendiente | J15: Ver Tarifario Maestro 2026 | K15: Deal Coca-Cola y X Gear cerrados; peleó Supernova. Tarifa top de la red
A16: Gambetiti | B16: Fútbol / Creator | C16: Fútbol, Apuestas, Bebidas | D16: KATANA — Operable | H16: @gambetiti | I16: Pendiente | J16: Ver Tarifario Maestro 2026 | K16: Deal Supernova y Mas Color Mundial cerrados
A17: Neux | B17: Gaming / Streaming | C17: Gaming, Tech, Telecom, Automotriz, Turismo | D17: KATANA — Operable | H17: @a_aguero19 / @neuxito | I17: Pendiente | J17: Ver Tarifario Maestro 2026 | K17: Bet Master always-on mensual; H2O Power
A18: Chuy Almada | B18: Fitness / Box | C18: Fitness, Box, Sportswear, Nutrición, Wellness, Combate | D18: KATANA — Chuy | H18: YouTube | I18: Pendiente | J18: Ver Tarifario Maestro 2026 | K18: PENDIENTE: completar bio, propuesta de valor, plataformas, métricas, assets, casos y restricciones. Categoría corregida por Jesús Gallardo el 2-ago-2026: fitness y box, no fútbol. | X18: PILOTO — FASE 1
A19: Yoiker | B19: Gaming / Streaming / Entretenimiento | C19: Gaming, Tech, Telecom, Eventos, Experiencias | D19: KATANA — Chuy | H19: Kick | I19: Pendiente | J19: Ver Tarifario Maestro 2026 | K19: No realiza streams. Sí realiza hosteo, con tarifa base desde $30,000 MXN. Escalera comercial validada: Reel IG $70,000; Post fijo IG $80,000; Reel Collab $85,000; TikTok + réplica espejo en Reel $140,000. Presencia en evento $60,000. TikTok audio musical pendiente de definir. Fuente: definición interna Chuy, 31-jul-2026.
A20: Kike Padilla / Rookie Leagues | B20: Béisbol / Streaming | C20: Béisbol, Gaming, Streaming, Tech, Eventos, Experiencias | D20: KATANA — Chuy | G20: 48.9K aprox. — validar | H20: Twitch | Kick | YouTube | I20: Pendiente | J20: Ver Tarifario Maestro 2026 | K20: Peleó preliminar Supernova 2025
A21: Stephany TV | B21: Gaming / Streaming / Entretenimiento | C21: Gaming, Tech, Telecom, Lifestyle, Eventos | D21: KATANA — Chuy | H21: Twitch / Kick — confirmar | I21: Pendiente | J21: Tarifario pendiente
A22: Padigol / Santiago Padilla | B22: Fútbol / Música | C22: Fútbol, Música, Bebidas, Streaming, Entretenimiento | D22: KATANA — Operable | H22: Podcast / Video | I22: Pendiente | J22: Ver Tarifario Maestro 2026 — histórico capturado, no vigente | K22: PILOTO — FASE 1. Tarifario histórico previo al Mundial capturado el 2-ago-2026. Incluye canales propios de Padigol y canales del Podcast de Padilla como inventarios separados. Falta incorporar Crónicas de Música y validar tarifas actuales antes de cotizar. | X22: PILOTO — FASE 1
A23: Edgar Cháirez | B23: MMA / UFC | C23: Bebidas, Apuestas, Sportswear, Fitness | D23: KATANA — Operable | I23: Pendiente | J23: Caso por caso — agregar al Tarifario Maestro
K24: Talento histórico de Chuy
K28: Deal Emergent AI cerrado
K29: Amazon: 3 campañas cerradas
K31: Tiene 350 mil seguidores. Reel IG actualizado a $50,000; Story a $15,000; la fijación se entiende específicamente como publicación fijada durante 7 días. No aplica masterclass. Puede venderse individualmente o como paquete familiar con Tejón; el paquete conjunto se cotiza caso por caso. Fuente: definición interna Chuy, 31-jul-2026. Pendiente aprobación de Ramiro.
K32: Actual campeón mundial de calistenia. Tarifas base comprobadas en Tabulador HONOR: TikTok $30,000; Reel IG $60,000; TikTok + Reel espejo $80,000; Story $25,000. El resto son propuestas internas aceptadas por Chuy y pendientes de aprobación de Ramiro. Reel Collab permanece pendiente para no confundirlo con TikTok + réplica espejo en Reel. Fuente: Tabulador HONOR + definición interna Chuy, 31-jul-2026. | V32: Colombia | W32: Por validar
K34: YouTube Live es su plataforma principal para streaming. Twitch y Kick quedan como plataformas disponibles sin tarifa automática; se cotizan caso por caso. Reel IG corregido a $50,000 MXN y Reel Collab a $60,000 MXN. Podcast: referencia mensual de $150,000 MXN, sujeta a formato, número de episodios e integración. Fuente: definición interna Chuy, 31-jul-2026. Propuesta interna pendiente de aprobación de Ramiro.
K36: HBO negociando 2 TikToks $180k
K38: Top podcast de fútbol; formato audio+video, cruce natural con Mar Coronel y patrocinios de apuestas
K41: Gaming y entretenimiento; opción para torneos, apariciones y experiencias. YouTube disponible: video dedicado, integración dentro de video y YouTube Short; tarifas pendientes de definir. Mantener como propuesta interna hasta aprobación. | L41: Pendiente | M41: Pendiente | N41: Pendiente | O41: Pendiente | P41: Pendiente | Q41: Pendiente | R41: Sin precio aprobado | S41: Por definir con Chuy | U41: Definir unitarios antes de ofrecer.
K42: Agregar al roster comercial de Chuy. YouTube es una de sus plataformas fuertes. No inventar tarifas; definir video dedicado, integración y Short antes de presentar. Fuente: definición interna Chuy, 31-jul-2026. Pendiente aprobación interna. | L42: Pendiente | M42: Pendiente | N42: Pendiente | O42: Pendiente | P42: Pendiente | Q42: Pendiente | R42: Sin precio aprobado | S42: Por definir con Chuy | U42: Definir categoría y handles al validar.
K43: Kick es su plataforma principal de streaming. Tarifas base de contenido tomadas del tabulador HONOR; complementos definidos internamente por Chuy. Pendiente aprobación de Ramiro. | L43: Pendiente | M43: Pendiente | N43: Pendiente | O43: Pendiente | P43: Pendiente | Q43: Pendiente | R43: Sin precio aprobado | S43: Por definir con Chuy | U43: Definir categoría y handles al validar.
K44: Se mantiene en el roster comercial de Chuy. Tiene inventario potencial en Twitch y/o Kick; confirmar plataforma principal, formatos y tarifas antes de presentar a cliente. No inventar precios. Fuente: instrucción interna Chuy, 31-jul-2026. | L44: Pendiente | M44: Pendiente | N44: Pendiente | O44: Pendiente | P44: Pendiente | Q44: Pendiente | R44: Sin precio aprobado | S44: Por definir con Chuy | U44: Más viáticos internacionales cuando aplique. | V44: Colombia | W44: Por validar
K45: Talento operable en Honduras; sujeto a validación de métricas y relación. | L45: Pendiente | M45: Pendiente | N45: Pendiente | O45: Pendiente | P45: Pendiente | Q45: Pendiente | R45: Sin precio aprobado | S45: Por definir con Chuy | U45: Más viáticos internacionales cuando aplique. | V45: Honduras | W45: Por validar
K46: Talento operable en Costa Rica; sujeto a validación de métricas y relación. | L46: Pendiente | M46: Pendiente | N46: Pendiente | O46: Pendiente | P46: Pendiente | Q46: Pendiente | R46: Sin precio aprobado | S46: Por definir con Chuy | U46: Más viáticos internacionales cuando aplique. | V46: Costa Rica | W46: Por validar
K47: Talento operable en Panamá; sujeto a validación de métricas y relación. | L47: Pendiente | M47: Pendiente | N47: Pendiente | O47: Pendiente | P47: Pendiente | Q47: Pendiente | R47: Sin precio aprobado | S47: Por definir con Chuy | U47: Más viáticos internacionales cuando aplique. | V47: Panamá | W47: Por validar
K48: Perfil operable para viajes, pareja, lifestyle y experiencias de destino. | L48: Pendiente | M48: Pendiente | N48: Pendiente | O48: Pendiente | P48: Pendiente | Q48: Pendiente | R48: Sin precio aprobado | S48: Por definir con Chuy | U48: Definir tarifas unitarias y paquete con Diana por separado. | V48: México | Y48: Por validar
K49: Perfil individual y participación posible en dupla con Chuy Alma. | M49: Pendiente | N49: Pendiente | O49: Pendiente | P49: Pendiente | Q49: Pendiente | R49: Sin precio aprobado | S49: Por definir con Chuy | U49: Definir tarifas individuales y precio especial en dupla. | Y49: Por validar
...

Sheet TALENTOS_BACKUP_2026-08-01
A1: Talento | B1: Categoría | C1: Verticales que abre | D1: Tipo (casa / aliado) | E1: IG seguidores | F1: TikTok seguidores | G1: YouTube subs | H1: Otras plataformas | I1: Media kit HTML | J1: Tarifa base referencia (MXN) | K1: Notas / ángulo comercial | V1: País / mercado | W1: Estatus network | X1: Prioridad comercial | Y1: Disponibilidad
A2: Divino Espinoza | B2: Box — Campeón del mundo | C2: Bebidas, Apuestas, Sportswear, Streaming (historia sin contar) | D2: KATANA — Casa | I2: Pendiente | J2: Caso por caso | Presencia de marca en short de pelea: $750,000 MXN por combate | K2: Activo premium de box. La cifra de $750,000 MXN aplica como referencia para presencia de marca en el short durante el combate. Puede ampliarse a ropa de entrenamiento, llegada, pesaje, conferencia o contenido asociado según el paquete. Sujeto a evento, rival, transmisión, ubicación del logo, derechos, exclusividad y aprobación final. Fuente: definición interna Chuy, 31-jul-2026. Pendiente aprobación de Ramiro.
A3: Lazy Boy | B3: MMA / UFC — Mediático | C3: Bebidas, Apuestas, Sportswear, Grooming | D3: KATANA — Aliado (definir) | I3: Pendiente | J3: Caso por caso | K3: Atleta de alto rendimiento. Contenido digital, presencia en eventos, patrocinios deportivos, campamento, ropa y activaciones se cotizan caso por caso según marca, alcance, evento, derechos, exclusividad y disponibilidad. Fuente: definición interna Chuy, 31-jul-2026. Pendiente aprobación de Ramiro.
A4: Luis Pride | B4: MMA | C4: Bebidas, Apuestas, Sportswear, Nutrición | D4: KATANA — Casa | I4: Pendiente | J4: TikTok 150,000 | Reel IG 130,000 | TikTok + réplica espejo en Reel 225,000 | Reel Collab 180,000 | Post fijo IG 100,000 | Story 40,000 | Fijación 7 días 20,000 | Presencia 120,000 | Exclusividad mensual 50,000 | Stream 75,000 | Podcast N/A | Masterclass/experiencia 150,000 | Fee base por pelear 450,000 | TikTok audio musical pendiente | K4: Regla de espejo aplicada: 1.5x el precio más alto entre TikTok y Reel IG. Fee base por pelear: $450,000 MXN. Fuente: definición interna Chuy, 31-jul-2026.
A5: Ronny | B5: Box | C5: Bebidas, Apuestas, Sportswear, Nutrición | D5: KATANA — Casa | I5: Twitch | J5: TikTok 90,000 | Reel IG 130,000 | Reel Collab 150,000 | Post fijo IG 80,000 | Story 40,000 | Publicación fijada durante 7 días 15,000 | Presencia 100,000 | Exclusividad mensual 40,000 | Stream en Twitch 50,000 | Podcast N/A | Masterclass/experiencia 150,000 | Fee base por pelear 250,000 | K5: Streamer también activo en Twitch. La tarifa de stream registrada corresponde a Twitch. Fee base por pelear: $250,000 MXN. Fuente: Tabulador HONOR + ajustes internos de Chuy, 31-jul-2026. Propuesta interna pendiente de aprobación de Ramiro.
A6: Tejón de la Miel | B6: Box — Promesa (12 años) | C6: Familia & Kids, Sportswear, Alimentos | D6: KATANA — Casa | I6: Pendiente | J6: TikTok 100,000 | Reel IG 150,000 | Reel Collab 180,000 | Post fijo IG 80,000 | Story 40,000 | Fijación 7 días 15,000 | Presencia 100,000 | Exclusividad mensual 40,000 | Stream 50,000 | Podcast N/A | Masterclass/experiencia 150,000 | Peleas desde 50,000 | K6: TikTok igual a Mariel Estrella. Reel IG corregido a $150,000 y Reel Collab a $180,000. Peleas desde $50,000 MXN, sujeto a rival, evento, transmisión, ciudad, viáticos, exposición de marca y condiciones deportivas. Menor de edad: requiere autorización de tutor, revisión legal y aprobación interna. Fuente: definición interna Chuy, 31-jul-2026. Pendiente aprobación de Ramiro.
A7: César de la Parra | B7: Chef — Alto perfil | C7: Alimentos & Gastro, Bebidas, Electrodomésticos, Delivery, Turismo | D7: KATANA — Acceso exclusivo | I7: Pendiente | J7: Caso por caso | K7: Perfil altamente selectivo. Solo considerar marcas con afinidad real y aprobación expresa del talento. Priorizar acuerdos anuales, embajadurías de largo plazo o proyectos extraordinarios con alto valor creativo, gastronómico o reputacional. No manejar tarifario estándar ni cotizar por pieza aislada salvo excepción estratégica. Fuente: definición interna Chuy, 31-jul-2026. Requiere revisión de Jesús y Ramiro antes de presentar.
A8: Mar Coronel | B8: Fútbol — Up & coming / Tipster | C8: Apuestas & Fantasy, Financiero, Snacks, Telcos | D8: KATANA — Casa | I8: Pendiente | K8: Especializada en pronósticos/tips. Perfil ideal casas de apuestas.
A9: Nene Creative | B9: Gaming — #1 Rocket League | C9: Gaming, Tech & Telecom, Automotriz, Energy | D9: KATANA — Casa | I9: Twitch | YouTube | J9: TikTok 70,000 | Reel IG 40,000 | Reel Collab 35,000 | Post fijo IG 30,000 | Story 15,000 | Publicación fijada durante 7 días 10,000 | Presencia en evento 80,000 | Exclusividad mensual 25,000 | Stream en Twitch para evento 60,000 | Stream dedicado en Twitch para marca 120,000 por hora | Integración de marca en stream caso por caso | Podcast N/A | Masterclass/experiencia 100,000 | YouTube pendiente | K9: Twitch es su plataforma principal de streaming. Stream dedicado para marca: $120,000 MXN por hora. Integraciones dentro de streams existentes se cotizan caso por caso. YouTube disponible: video dedicado, integración y Short; tarifas pendientes. Fuente: definición interna Chuy, 31-jul-2026. Pendiente aprobación de Ramiro.
A10: Julio Orozco | B10: Música | C10: Bebidas, Festivales, Ticketing, Moda, Nightlife | D10: KATANA — Casa | I10: Kick | YouTube | J10: TikTok 30,000 | Reel IG 70,000 | Reel Collab 100,000 | Post fijo IG 50,000 | Story 30,000 | Publicación fijada durante 7 días 20,000 | Hosteo 80,000 | Stream en Kick para evento 50,000 | Podcast mensual 150,000 por 4 capítulos | Masterclass N/A | Exclusividad mensual 60,000 | YouTube pendiente | K10: Kick es su plataforma principal de streaming. YouTube disponible: video dedicado, integración dentro de video y Short; tarifas pendientes. Fuente: definición interna Chuy, 31-jul-2026. Propuesta interna pendiente de aprobación de Ramiro.
A11: Mariel Estrella | B11: Fitness / Lifestyle — Up & coming | C11: Belleza & Wellness, Sportswear, Apps, Healthy food | D11: KATANA — Casa | I11: Pendiente | K11: Cierres en curso — empujar.
A12: Mariely | B12: Fútbol | C12: Apuestas, Bebidas, Snacks, Telcos | D12: KATANA — Casa | I12: Pendiente | K12: POSIBLE DUPLICADO: ¿Mariely = Mar Coronel (Marieli Coronel)? Confirmar y consolidar.
A13: Juan de Dios G | B13: Storytime/Vlogging — Macro | C13: Entretenimiento, Bebidas, Apps | D13: KIF (red comercial) | H13: @juanddiosg | I13: Pendiente | J13: TikTok 200,000 | Reel IG 160,000 | TikTok + réplica espejo en Reel 240,000 | Post fijo IG 100,000 | Story 60,000 | Publicación fijada durante 7 días 25,000 | Presencia en evento 150,000 | Exclusividad mensual 75,000 | Promoción de audio musical en TikTok pendiente | K13: Tarifario construido con definición directa de Chuy. TikTok + réplica espejo en Reel se mantiene por encima del TikTok individual. Publicación fijada durante 7 días y exclusividad mensual se cotizan por separado. TikTok audio musical: pendiente de definir. Fuente: definición interna Chuy, 31-jul-2026. No incluye IVA, producción, viáticos, pauta ni derechos de uso adicionales.
A14: Javetas | B14: Fútbol/Vlogging — Macro | C14: Fútbol, Apuestas, Bebidas | D14: KIF (red comercial) | H14: @javetasenelarco | I14: Pendiente | K14: Rates altos; propuesto Viuda de Romero $4M
A15: Mercedes Roa | B15: Fútbol — Macro top | C15: Fútbol, Bebidas, Sportswear | D15: KIF (red comercial) | H15: @mercedes_roa | I15: Pendiente | K15: Deal Coca-Cola y X Gear cerrados; peleó Supernova. Tarifa top de la red
A16: Yoz Gless | B16: Fútbol femenil | C16: Fútbol, Apuestas | D16: KIF (red comercial) | H16: @yoz_gless_ | I16: Pendiente | K16: Deal Supernova y Mas Color Mundial cerrados
A17: Nikkole Teja | B17: Fútbol femenil | C17: Fútbol, Apuestas, Bebidas | D17: KIF (red comercial) | H17: @nikkoleteja_ | I17: Pendiente | K17: Bet Master always-on mensual; H2O Power
A18: Canelo Angulo | B18: Fútbol / ex-jugador | C18: Fútbol, Apuestas (tipster) | D18: KIF (red comercial) | H18: @jrangulo19 | I18: Pendiente | K18: Cliente TipsterPages y eBay; DT All Stars
A19: Gambetiti | B19: Fútbol-creator | C19: Fútbol, Apuestas, Bebidas | D19: KIF (red comercial) | H19: @gambetiti | I19: Pendiente | J19: TikTok 100,000 | Reel IG 70,000 | TikTok + réplica espejo en Reel 140,000 | Reel Collab 85,000 | Post fijo IG 80,000 | Story 25,000 | Publicación fijada durante 7 días 10,000 | Presencia en evento 60,000 | Hosteo desde 30,000 | Exclusividad mensual 30,000 | TikTok audio musical pendiente | Podcast N/A | Masterclass/experiencia N/A | Stream N/A | K19: No realiza streams. Sí realiza hosteo, con tarifa base desde $30,000 MXN. Escalera comercial validada: Reel IG $70,000; Post fijo IG $80,000; Reel Collab $85,000; TikTok + réplica espejo en Reel $140,000. Presencia en evento $60,000. TikTok audio musical pendiente de definir. Fuente: definición interna Chuy, 31-jul-2026.
A20: Ian Granados | B20: Fútbol-creator | C20: Fútbol, Familia | D20: KIF (red comercial) | H20: @ian.granados1 | I20: Pendiente | K20: Peleó preliminar Supernova 2025
A21: Mariana Grimaldi | B21: Comedy/Lifestyle — Macro | C21: Lifestyle, Bebidas, Beauty | D21: KIF (red comercial) | H21: @marianagrimaldi__ | I21: Pendiente
A22: Kozue | B22: Lifestyle/Entretenimiento — Macro | C22: Lifestyle, Tech | D22: KIF (red comercial) | H22: @kozuehayashii | I22: Pendiente
A23: Camila Sánchez | B23: TikTok/Lifestyle | C23: Lifestyle, Beauty | D23: KIF (red comercial) | H23: @camilasanchhez | I23: Pendiente
A24: Luisito Rey | B24: Comedy/Sketch | C24: Entretenimiento, Alimentos | D24: KIF (red comercial) | H24: @luisitorey | I24: Pendiente | K24: Talento histórico de Chuy
A25: Soy Mirrey Bro | B25: Luxury lifestyle — Macro | C25: Lifestyle, Bebidas premium | D25: KIF (red comercial) | H25: @soymirreybro | I25: Pendiente
A26: Edwin Mendoza | B26: Sports — Macro | C26: Fútbol, Sportswear | D26: KIF (red comercial) | H26: @edwinmendozza | I26: Pendiente
A27: Javier Rojo | B27: Sports/Gymnastics | C27: Fitness, Sportswear | D27: KIF (red comercial) | H27: @javierrojomx | I27: Pendiente
A28: Marurista | B28: Lifestyle — Macro | C28: Lifestyle, Tech | D28: KIF (red comercial) | H28: @marurista | I28: Pendiente | K28: Deal Emergent AI cerrado
A29: Ana Fer Lemus | B29: Lifestyle — Macro | C29: Lifestyle, E-commerce | D29: KIF (red comercial) | H29: @anafer.lemus | I29: Pendiente | K29: Amazon: 3 campañas cerradas
A30: Yetus Prime | B30: Entretenimiento — Macro | C30: Entretenimiento, Gaming | D30: KIF (red comercial) | H30: @yetus_prime | I30: Pendiente
A31: Mamá Tejona | B31: Familia / Lifestyle / Box | C31: Familia & Kids, Sportswear, Alimentos, Wellness | D31: KATANA — Ecosistema Tejón | E31: 350000 | I31: Pendiente | J31: TikTok 25,000 | Reel IG 50,000 | Reel Collab 40,000 | Post fijo IG 20,000 | Story 15,000 | Publicación fijada durante 7 días 5,000 | Presencia 15,000 | Exclusividad mensual 10,000 | Stream 15,000 | Podcast N/A | Masterclass/experiencia N/A | K31: Tiene 350 mil seguidores. Reel IG actualizado a $50,000; Story a $15,000; la fijación se entiende específicamente como publicación fijada durante 7 días. No aplica masterclass. Puede venderse individualmente o como paquete familiar con Tejón; el paquete conjunto se cotiza caso por caso. Fuente: definición interna Chuy, 31-jul-2026. Pendiente aprobación de Ramiro.
A32: Tony Gastélum | B32: Calistenia / Fitness — Campeón mundial vigente | C32: Sportswear, Fitness, Nutrición, Wellness, Tech deportiva | D32: KATANA — Casa | I32: Pendiente | J32: TikTok 30,000 | TikTok + réplica espejo en Reel 80,000 | Reel IG 60,000 | Reel Collab pendiente | Post fijo IG 40,000 | Story 25,000 | Publicación fijada durante 7 días 10,000 | Presencia en evento 50,000 | Exclusividad mensual 25,000 | Stream en evento 40,000 | Stream dedicado para marca 80,000 por hora | Integración de marca en stream caso por caso | Podcast N/A | Masterclass/experiencia 80,000 | K32: Actual campeón mundial de calistenia. Tarifas base comprobadas en Tabulador HONOR: TikTok $30,000; Reel IG $60,000; TikTok + Reel espejo $80,000; Story $25,000. El resto son propuestas internas aceptadas por Chuy y pendientes de aprobación de Ramiro. Reel Collab permanece pendiente para no confundirlo con TikTok + réplica espejo en Reel. Fuente: Tabulador HONOR + definición interna Chuy, 31-jul-2026. | V32: Colombia | W32: Por validar
A33: Ramón Villa | B33: Sports — Macro | C33: Fútbol, Sportswear | D33: KIF (red comercial) | H33: @ramonvillazg | I33: Pendiente
A34: Mike Máquina del Mal | B34: Streamer #1 Fútbol | C34: Fútbol, Apuestas, Gaming, Streaming — Fórmula S (host) | D34: KIF (red comercial) | H34: @mikemaquinadelmalshow | I34: YouTube Live | YouTube | Twitch | Kick | J34: TikTok 100,000 | Reel IG 50,000 | Reel Collab 60,000 | Post fijo IG 60,000 | Story 30,000 | Publicación fijada durante 7 días 15,000 | Presencia en evento 80,000 | Exclusividad mensual 40,000 | Stream dedicado en YouTube Live para marca 100,000 por hora | Integración dentro de live caso por caso | Podcast mensual 150,000 | Masterclass/experiencia 100,000 | Promoción de audio musical en TikTok pendiente | K34: YouTube Live es su plataforma principal para streaming. Twitch y Kick quedan como plataformas disponibles sin tarifa automática; se cotizan caso por caso. Reel IG corregido a $50,000 MXN y Reel Collab a $60,000 MXN. Podcast: referencia mensual de $150,000 MXN, sujeta a formato, número de episodios e integración. Fuente: definición interna Chuy, 31-jul-2026. Propuesta interna pendiente de aprobación de Ramiro.
A35: Espe Borras | B35: Sports | C35: Fútbol | D35: KIF (red comercial) | H35: @espe | I35: Pendiente
A36: Geryna Sotelo | B36: Sports | C36: Fútbol, Streaming | D36: KIF (red comercial) | H36: @GerynaSotelo | I36: Pendiente | K36: HBO negociando 2 TikToks $180k
A37: Los Futbolitos | B37: Sports/Podcast — Macro | C37: Fútbol, Snacks | D37: KIF (red comercial) | H37: @losfutbolitostv | I37: Pendiente
A38: Padigol | B38: Podcast — Top Podcast Fútbol | C38: Fútbol, Apuestas, Bebidas, Streaming | D38: KIF (red comercial) | I38: Pendiente | K38: Top podcast de fútbol; formato audio+video, cruce natural con Mar Coronel y patrocinios de apuestas
A41: Neux | B41: Gaming / Rocket League / Streaming | C41: Gaming, Tech, Telecom, Automotriz, Turismo | D41: KATANA — Operable | H41: @a_aguero19 / @neuxito | I41: Pendiente | K41: Gaming y entretenimiento; opción para torneos, apariciones y experiencias. YouTube disponible: video dedicado, integración dentro de video y YouTube Short; tarifas pendientes de definir. Mantener como propuesta interna hasta aprobación. | L41: Pendiente | M41: Pendiente | N41: Pendiente | O41: Pendiente | P41: Pendiente | Q41: Pendiente | R41: Sin precio aprobado | S41: Por definir con Chuy | U41: Definir unitarios antes de ofrecer.
A42: Chuy Almada | B42: YouTube / Entretenimiento / Lifestyle | C42: Entretenimiento, Lifestyle, Cultura, Marcas de consumo, Experiencias | D42: KATANA — Chuy | I42: Pendiente | J42: YouTube disponible: video dedicado | integración dentro de video | YouTube Short | Tarifas pendientes | K42: Agregar al roster comercial de Chuy. YouTube es una de sus plataformas fuertes. No inventar tarifas; definir video dedicado, integración y Short antes de presentar. Fuente: definición interna Chuy, 31-jul-2026. Pendiente aprobación interna. | L42: Pendiente | M42: Pendiente | N42: Pendiente | O42: Pendiente | P42: Pendiente | Q42: Pendiente | R42: Sin precio aprobado | S42: Por definir con Chuy | U42: Definir categoría y handles al validar.
...

Sheet MARCAS TARGET
A1: SEÑALÉTICA: | B1: ACTIVO — ya hay contacto real / cerrado | C1: A UN PASO — contrato / por firmar | D1: EN PROCESO — negociación / propuesta / tibio | E1: FRÍO — target, aún sin contactar | F1: PERDIDO / DORMIDO — reactivar o descartar
A2: Vertical | B2: Marca | C2: ¿Relación previa? | D2: Por qué es target | E2: Talento que le pega | F2: Agencia que la maneja (si se sabe) | G2: Decision-maker (nombre) | H2: Cargo | I2: Fuente del dato | J2: Pasado a LEADS
A3: Bebidas | B3: Cerveza Victoria | C3: Sí - pasada | D3: Ya ha invertido con nosotros | E3: Pool Combate (paquete) | I3: Relación Chuy | J3: No
A4: Tech & Telecom | B4: Honor | C4: Sí - pasada | D4: Ya ha invertido con nosotros; gasta fuerte en creators MX | E4: Nene Creative | I4: Relación Chuy | J4: No
A5: Apuestas & Fantasy | B5: Caliente | C5: Sí - activa | D5: Líder local; sin programa público de afiliados — entra por relación || Gambetiti CERRADO por firmar; Rivaldios 3 historias/mes; Luis Pride propuesta enviada. Contacto: Pony | E5: Mar Coronel | I5: Scouting Claude | J5: No
A6: Apuestas & Fantasy | B6: Betano | C6: No | D6: Crecimiento fuerte en la región, patrocinios Liga MX | E6: Pool Combate (paquete) | I6: Scouting Claude | J6: No
A7: Apuestas & Fantasy | B7: Playdoit | C7: No | D7: Mencionada por Chuy como target | E7: Mar Coronel | I7: Chuy | J7: No
A8: Streaming & Entretenimiento | B8: Netflix | C8: Sí - pasada | D8: Bahía Colorada #1 — historial con contenido | E8: Varios / Pool mixto | I8: Relación Chuy | J8: No
A9: Streaming & Entretenimiento | B9: Paramount | C9: No | D9: Mencionada por Chuy | E9: Varios / Pool mixto | I9: Chuy | J9: No
A10: Streaming & Entretenimiento | B10: Kick | C10: Sí - pasada | D10: Broadcast Fórmula S | E10: Varios / Pool mixto | I10: Relación | J10: No
A11: Bebidas | B11: Grupo Modelo (corporativo) | C11: No | D11: Mayor anunciante cervecero MX; estrategia basada en creators, eventos masivos y cultura | E11: Pool Combate (paquete) | G11: Felipe Ambra | H11: VP de Marketing | I11: Forbes MX, may 2026 | J11: No
A12: Bebidas | B12: Cerveza Victoria | C12: Sí - pasada | D12: Ya invirtió con nosotros; marca top-6 más valiosa de MX (Kantar BrandZ) | E12: Pool Combate (paquete) | G12: Gabriel Díaz | H12: Director de Cerveza Victoria | I12: Produ/Kantar, mar 2025 — confirmar en LinkedIn | J12: No
A13: Bebidas | B13: Corona | C13: No | D13: Marca #1 más valiosa de MX; plataformas de música, deporte y entretenimiento | E13: Varios / Pool mixto | G13: Marcela Treviño / Yune Aranguren | H13: Directora de Corona / Directora Marcas Core (Corona y Victoria) | I13: Produ/Kantar, mar 2025 — confirmar en LinkedIn | J13: No
A14: Bebidas | B14: Cerveza Modelo | C14: No | D14: Top-3 marca más valiosa MX | E14: Pool Combate (paquete) | G14: César Alcántara | H14: Director de Cerveza Modelo | I14: Produ/Kantar, mar 2025 — confirmar en LinkedIn | J14: No
A15: Bebidas | B15: Grupo Modelo — Marcas Premium | C15: No | D15: Pacífico, premium portfolio | E15: Julio Orozco | G15: Mariana Cuellar | H15: Directora de Marcas Premium | I15: Produ/Kantar, mar 2025 — confirmar en LinkedIn | J15: No
A16: Bebidas | B16: HEINEKEN México (corporativo) | C16: No | D16: Tecate, Indio, Dos Equis, Bohemia; campañas digitales con influencers (Tecate 0.0: 106 piezas, 99% audiencia digital) | E16: Pool Combate (paquete) | F16: LePub Mexico City (creativa de Tecate) | G16: Marta García | H16: VP de Marketing | I16: Comunicado Heineken MX ~2024 — confirmar en LinkedIn | J16: No
A17: Bebidas | B17: HEINEKEN — Marcas Premium | C17: No | D17: Heineken, Amstel Ultra (activaciones deporte: pádel, F1) | E17: Mariel Estrella | G17: Karla Patricia González Álvarez | H17: Directora de Marcas Premium | I17: Milenio, dic 2024 — confirmar en LinkedIn | J17: No
A18: Bebidas | B18: HEINEKEN — Media | C18: No | D18: Decide inversión en medios y digital de todo el portafolio | E18: Varios / Pool mixto | G18: Pablo Alfredo Rada | H18: Director de Media & CDAU | I18: Milenio, dic 2024 — confirmar en LinkedIn | J18: No
A19: Bebidas | B19: Tecate | C19: No | D19: Marca más premiada de MX en Clio 2026; festival Pa'l Norte; combate/box es territorio histórico de Tecate | E19: Pool Combate (paquete) | F19: LePub Mexico City | I19: Merca 2.0, abr 2026 | J19: No
A20: Bebidas | B20: Indio | C20: No | D20: Campañas de barrio/cultura urbana (Tanderos, Mexologia) | E20: Julio Orozco | I20: Prensa Heineken 2025 | J20: No
A21: Tech & Telecom | B21: Honor México | C21: Sí - activa | D21: Ya invirtió con nosotros; muy activa en marketing MX || Deal en proceso con Rivaldios (contacto: Francisco); histórico con Katana | E21: Nene Creative | G21: Julio Meneses | H21: CMO / Director de Marketing México | I21: LinkedIn + Isopixel — confirmar vigencia | J21: No
A22: Tech & Telecom | B22: Honor Latam | C22: No | D22: Capa regional que aprueba presupuestos grandes | E22: Nene Creative | G22: Jesús Quintero | H22: Head de Marketing Latinoamérica | I22: El Financiero, oct 2024 — confirmar en LinkedIn | J22: No
A23: Tech & Telecom | B23: Telcel | C23: Sí - pasada | D23: COMPROBADO: patrocinó Supernova Strikers 2025 (10M+ viewers). Compra creator boxing MX || Propuesta anual CPA $3.25M enviada (31 talentos, modelo costo por acción) | E23: Pool Combate (paquete) | I23: Merca 2.0, ago 2025 | J23: No
A24: Alimentos & Gastro | B24: Farmacias Similares | C24: No | D24: COMPROBADO: patrocinó Supernova Strikers 2025 | E24: Varios / Pool mixto | I24: Merca 2.0, ago 2025 | J24: No
A25: Streaming & Entretenimiento | B25: DAZN | C25: No | D25: COMPROBADO: transmitió Supernova; plataforma global de combate. Target para derechos FIERA | E25: Pool Combate (paquete) | I25: Merca 2.0, ago 2025 | J25: No
A26: Streaming & Entretenimiento | B26: Podimo | C26: No | D26: COMPROBADO: patrocinó Supernova Strikers 2025; compra audio/creators | E26: Julio Orozco | I26: Merca 2.0, ago 2025 | J26: No
A27: Alimentos & Gastro | B27: Domino's Pizza | C27: No | D27: COMPROBADO: patrocinó Supernova 2025; cliente de BrandMe | E27: Varios / Pool mixto | F27: BrandMe (influencer mkt) | I27: Merca 2.0, ago 2025 | J27: No
A28: Alimentos & Gastro | B28: McCormick | C28: No | D28: COMPROBADO: patrocinó Supernova 2025 Y repite en Génesis 2026. Fit natural con César (chef) | E28: César de la Parra | I28: Merca 2.0 + El Financiero | J28: No
A29: Streaming & Entretenimiento | B29: Cinépolis | C29: No | D29: COMPROBADO: patrocinó y transmitió Supernova en salas | E29: Varios / Pool mixto | I29: Merca 2.0, ago 2025 | J29: No
A30: Alimentos & Gastro | B30: Sabritas (PepsiCo) | C30: No | D30: COMPROBADO: zona patrocinada Supernova Génesis 2026 | E30: Pool Combate (paquete) | I30: El Financiero, dic 2025 | J30: No
A31: Financiero & Fintech | B31: Elektra / Banco Azteca | C31: No | D31: COMPROBADO: zonas patrocinadas Supernova Génesis 2026. Banca popular compra creators | E31: Varios / Pool mixto | I31: El Financiero, dic 2025 | J31: No
A32: Familia & Kids | B32: Mercado Libre | C32: No | D32: COMPROBADO: zona patrocinada Supernova Génesis 2026; mayor anunciante e-commerce | E32: Varios / Pool mixto | I32: El Financiero, dic 2025 | J32: No
A33: Familia & Kids | B33: Miniso | C33: No | D33: COMPROBADO: zona patrocinada Supernova Génesis 2026; audiencia joven/familiar | E33: Tejón + Mamá (dupla familiar) | I33: El Financiero, dic 2025 | J33: No
A34: Bebidas | B34: Pepsi | C34: No | D34: COMPROBADO: zona patrocinada Supernova Génesis 2026 | E34: Pool Combate (paquete) | I34: El Financiero, dic 2025 | J34: No
A35: Tech & Telecom | B35: Toyota | C35: No | D35: COMPROBADO: zona patrocinada Supernova Génesis 2026. Automotriz+gaming: fit Nene (Rocket League=coches) | E35: Nene Creative | I35: El Financiero, dic 2025 | J35: No
A36: Tech & Telecom | B36: Mega (Megacable) | C36: No | D36: COMPROBADO: zona patrocinada Supernova Génesis 2026 | E36: Varios / Pool mixto | I36: El Financiero, dic 2025 | J36: No
A37: Bebidas | B37: Boing (Pascual) | C37: No | D37: COMPROBADO: zona patrocinada Supernova Génesis 2026 | E37: Tejón + Mamá (dupla familiar) | I37: El Financiero, dic 2025 | J37: No
A38: Bebidas | B38: Tecate (box) | C38: No | D38: DUEÑO histórico del territorio box MX: patrocina Canelo y box profesional ("Te hace falta ver más bax") | E38: Divino Espinoza | F38: LePub Mexico City | I38: InformaBTL + historial marca | J38: No
A39: Sportswear & Nutrición | B39: Under Armour | C39: No | D39: COMPROBADO: patrocina Canelo desde 2012; deportes de contacto es su territorio | E39: Divino Espinoza | I39: Radio Fórmula, 2024 | J39: No
A40: Sportswear & Nutrición | B40: Everlast | C40: No | D40: COMPROBADO: patrocina Canelo; marca endémica de box, entrada natural para todo el pool | E40: Pool Combate (paquete) | I40: Revista Clase, 2021 | J40: No
...

Sheet AGENCIAS
A1: SEÑALÉTICA: | B1: ACTIVO — ya hay contacto real / cerrado | C1: A UN PASO — contrato / por firmar | D1: EN PROCESO — negociación / propuesta / tibio | E1: FRÍO — target, aún sin contactar | F1: PERDIDO / DORMIDO — reactivar o descartar
A2: Agencia | B2: Tipo | C2: Marcas que maneja | D2: Ciudad | E2: Contacto clave | F2: Cargo | G2: Email | H2: LinkedIn | I2: ¿Relación previa? | J2: Notas | K2: Pasado a LEADS
A3: LePub Mexico City | B3: Agencia creativa | C3: Tecate (Heineken) — 20 medallas Clio 2026 | D3: CDMX | I3: No | J3: La agencia creativa más premiada de MX 2026. Puerta a Tecate. | K3: No
A4: BrandMe | B4: Agencia influencer mkt | C4: Disney, Jüsto, eBay, P&G, Domino's | D4: CDMX (Condesa) | I4: No | J4: Pionera en influencer mkt MX; plataforma + servicio 360. | K4: No
A5: Gamol | B5: Agencia influencer mkt | C5: Varios; "Best Influencer Agency" Fortune 2018-19 | D5: CDMX | I5: No | J5: Metodología de selección de talento; posible aliado o competencia. | K5: No
A6: Dinametra | B6: Agencia influencer mkt | C6: Red de 35,000+ influencers | D6: CDMX | I6: No | J6: Orientada a performance; YouTube/TikTok/Twitch. | K6: No
A7: INPULSE Digital | B7: Agencia influencer mkt | C7: Entretenimiento y música (LATAM/US) | D7: CDMX / Miami | I7: No | J7: Data + narrativa visual; fuerte en entertainment. | K7: No
A8: BWE Agency | B8: Agencia influencer mkt | C8: Rappi, Coca-Cola, Samsung | D8: CDMX | I8: No | J8: Puerta indirecta a Samsung y Coca-Cola. | K8: No
A9: SUBE | B9: Agencia de medios | C9: Retail, automotriz, turismo, fintech, APUESTAS | D9: CDMX / Miami / Dallas | I9: No | J9: Trabaja vertical de apuestas — cruce directo con pool combate y Mar Coronel. | K9: No
